<?xml version="1.0" encoding="utf-8"?>
<!-- This URDF was automatically created by SolidWorks to URDF Exporter! Originally created by Stephen Brawner (brawner@gmail.com) 
     Commit Version: 1.5.1-0-g916b5db  Build Version: 1.5.7152.31018
     For more information, please see http://wiki.ros.org/sw_urdf_exporter -->
<robot
  name="robotbase">
  <link name="base_footprint"/>
  <joint name="base_joint" type="fixed">
    <parent link="base_footprint"/>
    <child link="base_link"/>
    <origin xyz="0.0 0.0 0.010" rpy="0 0 -1.5707"/>
  </joint>

  <link
    name="base_link">
    <inertial>
      <origin
        xyz="0.0317095416007534 0.00585954573908961 -0.0152243764730905"
        rpy="0 0 0" />
      <mass
        value="1.17424291261763" />
      <inertia
        ixx="0.00248432843336696"
        ixy="-1.47224274103694E-07"
        ixz="1.4747915255414E-05"
        iyy="0.00646656944346282"
        iyz="1.76186370908733E-06"
        izz="0.00420898613081866" />
    </inertial>
    <visual>
      <origin
        xyz="0 0 0"
        rpy="0 0 0" />
      <geometry>
        <mesh
          filename="package://robotbase/meshes/base_link.STL" />
      </geometry>
      <material
        name="">
        <color
          rgba="0.898039215686275 0.917647058823529 0.929411764705882 1" />
      </material>
    </visual>
    <collision>
      <origin
        xyz="0 0 0"
        rpy="0 0 0" />
      <geometry>
        <mesh
          filename="package://robotbase/meshes/base_link.STL" />
      </geometry>
    </collision>
  </link>
  <link
    name="wheel_1">
    <inertial>
      <origin
        xyz="0.0458771944899619 0.273062342112664 0.00546218671817029"
        rpy="0 0 0" />
      <mass
        value="2.11190311993617" />
      <inertia
        ixx="0.125143591732326"
        ixy="0.0213467042368404"
        ixz="0.00288420835824469"
        iyy="0.133607452018479"
        iyz="0.000848099165999844"
        izz="0.254298069907116" />
    </inertial>
    <visual>
      <origin
        xyz="0 0 0"
        rpy="0 0 0" />
      <geometry>
        <mesh
          filename="package://robotbase/meshes/wheel_1.STL" />
      </geometry>
      <material
        name="">
        <color
          rgba="0.792156862745098 0.819607843137255 0.933333333333333 1" />
      </material>
    </visual>
    <collision>
      <origin
        xyz="0 0 0"
        rpy="0 0 0" />
      <geometry>
        <mesh
          filename="package://robotbase/meshes/wheel_1.STL" />
      </geometry>
    </collision>
  </link>

  <link name = "hokuyo_link">
      <inertial>
          <mass value="0.1" />
          <origin xyz="0 0 0" rpy="0 0 0"/>
          <inertia ixx="1e-6" ixy="0" ixz="0" iyy="1e-6" iyz="0" izz="1e-6" />
      </inertial>
      <collision>
          <origin xyz = "0 0 0" rpy = "0 0 0"/>
          <geometry>
              <cylinder radius="0.05" length="0.1"/>
          </geometry>
      </collision>
      <visual>
          <origin xyz = "0 0 0" rpy = "0 0 0"/>
          <geometry>
              <mesh filename="package://robotbase/meshes/hokuyo.dae"/>
          </geometry>
      </visual>
  </link>

  <joint name ="hokuyo2world" type = "fixed">
      <axis xyz = "0 0 0" />
      <origin xyz="0 0 0.3" rpy="0 0 0"/>
      <parent link="base_footprint"/>
      <child link="hokuyo_link"/>
  </joint>

  <joint
    name="wheel_joint_1"
    type="continuous">
    <origin
      xyz="-0.205579586803807 0.205579586803807 0.025525"
      rpy="-3.12287874080334 0.00789732473317189 0.772154897409695" />
    <parent
      link="base_link" />
    <child
      link="wheel_1" />
    <axis
      xyz="0.0132424659193927 0.9997352674052 -0.0188157434779373" />
  </joint>
  <link
    name="wheel_2">
    <inertial>
      <origin
        xyz="0.0249361037302708 0.344076787772775 -0.00525954032226627"
        rpy="0 0 0" />
      <mass
        value="2.11190311993617" />
      <inertia
        ixx="0.176851164364651"
        ixy="0.0140731171262247"
        ixz="-0.0574672883301494"
        iyy="0.124722094801253"
        iyz="0.016639734965707"
        izz="0.211475854492017" />
    </inertial>
    <visual>
      <origin
        xyz="0 0 0"
        rpy="0 0 0" />
      <geometry>
        <mesh
          filename="package://robotbase/meshes/wheel_2.STL" />
      </geometry>
      <material
        name="">
        <color
          rgba="0.792156862745098 0.819607843137255 0.933333333333333 1" />
      </material>
    </visual>
    <collision>
      <origin
        xyz="0 0 0"
        rpy="0 0 0" />
      <geometry>
        <mesh
          filename="package://robotbase/meshes/wheel_2.STL" />
      </geometry>
    </collision>
  </link>
  <joint
    name="wheel_joint_2"
    type="continuous">
    <origin
      xyz="0.273359702677944 0.273359702677944 0.025524999999999"
      rpy="0.0283684725139944 0.624739352427002 2.37252145313176" />
    <parent
      link="base_link" />
    <child
      link="wheel_2" />
    <axis
      xyz="0.0132424659193958 0.9997352674052 -0.0188157434779366" />
  </joint>
  <link
    name="wheel_3">
    <inertial>
      <origin
        xyz="-0.0153682388591595 0.340029706879059 -0.000428568532610744"
        rpy="0 0 0" />
      <mass
        value="2.11190311993617" />
      <inertia
        ixx="0.158038000924784"
        ixy="0.00285067819372706"
        ixz="-0.0267302850342901"
        iyy="0.108281483822745"
        iyz="0.00660110986486032"
        izz="0.246729628910391" />
    </inertial>
    <visual>
      <origin
        xyz="0 0 0"
        rpy="0 0 0" />
      <geometry>
        <mesh
          filename="package://robotbase/meshes/wheel_3.STL" />
      </geometry>
      <material
        name="">
        <color
          rgba="0.792156862745098 0.819607843137255 0.933333333333333 1" />
      </material>
    </visual>
    <collision>
      <origin
        xyz="0 0 0"
        rpy="0 0 0" />
      <geometry>
        <mesh
          filename="package://robotbase/meshes/wheel_3.STL" />
      </geometry>
    </collision>
  </link>
  <joint
    name="wheel_joint_3"
    type="continuous">
    <origin
      xyz="0 -0.297733077767124 0.025525000000001"
      rpy="-3.11920659587766 -0.263132299010667 3.12787770373792" />
    <parent
      link="base_link" />
    <child
      link="wheel_3" />
    <axis
      xyz="0.0132424659193945 0.9997352674052 -0.0188157434779373" />
  </joint>

  <gazebo reference="wheel_1">
    <mu1>0.1</mu1>
    <mu2>0.1</mu2>
    <kp>500000.0</kp>
    <kd>10.0</kd>
    <minDepth>0.001</minDepth>
    <maxVel>0.1</maxVel>
    <fdir1>1 0 0</fdir1>
    <material>Gazebo/FlatBlack</material>
  </gazebo>

  <gazebo reference="wheel_2">
    <mu1>0.1</mu1>
    <mu2>0.1</mu2>
    <kp>500000.0</kp>
    <kd>10.0</kd>
    <minDepth>0.001</minDepth>
    <maxVel>0.1</maxVel>
    <fdir1>1 0 0</fdir1>
    <material>Gazebo/FlatBlack</material>
  </gazebo>

  <gazebo reference="wheel_3">
    <mu1>0.1</mu1>
    <mu2>0.1</mu2>
    <kp>500000.0</kp>
    <kd>10.0</kd>
    <minDepth>0.001</minDepth>
    <maxVel>0.1</maxVel>
    <fdir1>1 0 0</fdir1>
    <material>Gazebo/FlatBlack</material>
  </gazebo>

  <!-- hokuyo -->
    <gazebo reference="hokuyo_link">
      <sensor type="gpu_ray" name="head_hokuyo_sensor">
        <pose>0 0 0 0 0 0</pose>
        <visualize>true</visualize>
        <update_rate>40</update_rate>
        <ray>
          <scan>
            <horizontal>
              <samples>1080</samples>
              <resolution>1</resolution>
              <min_angle>-2.35619449</min_angle>
              <max_angle>2.35619449</max_angle>
            </horizontal>
          </scan>
          <range>
            <min>0.10</min>
            <max>30.0</max>
            <resolution>0.01</resolution>
          </range>
          <noise>
            <type>gaussian</type>
            <!-- Noise parameters based on published spec for Hokuyo laser
                 achieving "+-30mm" accuracy at range < 10m.  A mean of 0.0m and
                 stddev of 0.01m will put 99.7% of samples within 0.03m of the true
                 reading. -->
            <mean>0.0</mean>
            <stddev>0.01</stddev>
          </noise>
        </ray>
        <plugin name="gazebo_ros_hokuyo_controller" filename="libgazebo_ros_gpu_laser.so">
          <topicName>/scan</topicName>
          <frameName>hokuyo_link</frameName>
        </plugin>
      </sensor>
    </gazebo>

    <gazebo>
    <!-- If not have roopod_control_plugin -->
    <!-- <plugin name="object_controller" filename="libgazebo_ros_planar_move.so">
      <commandTopic>cmd_vel</commandTopic>
      <odometryTopic>odom</odometryTopic>
      <odometryFrame>odom</odometryFrame>
      <odometryRate>20.0</odometryRate>
      <robotbaseFrame>base_footprint</robotbaseFrame>
    </plugin> -->

    <!-- From lib fix slow gravity -->
    <plugin name="object_controller" filename="libropod_control_plugin.so">
      <commandTopic>cmd_vel</commandTopic>
      <odometryTopic>odom</odometryTopic>
      <odometryFrame>odom</odometryFrame>
      <odometryRate>20.0</odometryRate>
      <robotbaseFrame>base_footprint</robotbaseFrame>
    </plugin>
  </gazebo>

  <material name="black">
    <color rgba="0. 0. 0. 1" />
    <ambient>0.5 0.75 0 1</ambient>
    <diffuse>0 0 0 1</diffuse>
    <specular>0.2 0.2 0.2 64</specular>
    <emissive>0.1 0 0.1 1</emissive>
  </material>
  <material name="grey">
    <color rgba="0.6 0.6 0.6 1" />
    <ambient>0.5 0.75 0 1</ambient>
    <diffuse>0.6 0.6 0.6 1</diffuse>
    <specular>0.2 0.2 0.2 64</specular>
    <emissive>0.1 0 0.1 1</emissive>
  </material>
  <material name="white">
    <color rgba="0.9 0.9 0.9 1" />
    <ambient>0.5 0.75 0 1</ambient>
    <diffuse>0.9 0.9 0.9 1</diffuse>
    <specular>0.2 0.2 0.2 64</specular>
    <emissive>0.1 0 0.1 1</emissive>
  </material>

  <joint name = "camera_joint" type = "fixed">
      <axis xyz = "0 0 0" />
      <origin xyz="0 0 0.6" rpy="0 0 1.5707"/>
      <parent link="base_link"/>
      <child link="camera_base_link"/>
  </joint>

  <link name="camera_body">
    <inertial>
        <mass value="0.1" />
        <origin xyz="0 0 0" rpy="0 0 0"/>
        <inertia ixx="1e-6" ixy="0" ixz="0" iyy="1e-6" iyz="0" izz="1e-6" />
    </inertial>
    <collision>
        <origin xyz = "0 0 0" rpy = "0 0 0"/>
        <geometry>
            <box size="0.0994 0.0996 0.023" />
        </geometry>
    </collision>
    <visual>
      <origin xyz="0. 0. 0." />
      <geometry>
        <box size="0.0994 0.0996 0.023" />
      </geometry>
      <material name="white" />
    </visual>
  </link>

  <link name = "camera_base_link">
    <inertial>
        <mass value="0.1" />
        <origin xyz="0 0 0" rpy="0 0 0"/>
        <inertia ixx="1e-6" ixy="0" ixz="0" iyy="1e-6" iyz="0" izz="1e-6" />
    </inertial>
    <collision>
        <origin xyz = "-0.013 0. 0." rpy = "0 0 0"/>
        <geometry>
            <box size="0.026 0.103 0.039" />
        </geometry>
    </collision>
    <visual>
      <origin xyz="-0.013 0. 0." />
      <geometry>
        <box size="0.026 0.103 0.039" />
      </geometry>
      <material name="grey" />
    </visual>
  </link>

  <link name = "camera_visor">
    <inertial>
        <mass value="0.1" />
        <origin xyz="0 0 0" rpy="0 0 0"/>
        <inertia ixx="1e-6" ixy="0" ixz="0" iyy="1e-6" iyz="0" izz="1e-6" />
    </inertial>
    <collision>
        <origin xyz = "-0.0128 0. 0." rpy = "0 0 0"/>
        <geometry>
            <box size="0.026 0.101 0.037" />
        </geometry>
    </collision>
    <visual>
      <origin xyz="-0.0128 0. 0." />
      <geometry>
        <box size="0.026 0.101 0.037" />
      </geometry>
      <material name="black" />
    </visual>
  </link>

  <joint name="camera_base_to_body" type="fixed">
    <parent link="camera_base_link" />
    <child link="camera_body" />
    <origin xyz="-0.0757 0. 0.008" rpy="0. 0. 0." />
  </joint>

  <joint name="camera_base_to_visor" type="fixed">
    <parent link="camera_base_link" />
    <child link="camera_visor" />
    <origin xyz="0. 0. 0." rpy="0. 0. 0." />
  </joint>
  
  <link name = "optical_link">
        <!-- <inertial>
            <mass value="0.1" />
            <origin xyz="0 0 0" rpy="0 0 0"/>
            <inertia ixx="1e-6" ixy="0" ixz="0" iyy="1e-6" iyz="0" izz="1e-6" />
        </inertial>
        <collision>
            <origin xyz = "0 0 0" rpy = "0 0 0"/>
            <geometry>
                <cylinder radius="0.02" length="0.02"/>
            </geometry>
        </collision>
        <visual>
            <origin xyz = "0 0 0" rpy = "0 0 0"/>
            <geometry>
                <cylinder radius="0.02" length="0.02"/>
            </geometry>
        </visual> -->
    </link>

  <joint name = "optical_joint" type = "fixed">
      <axis xyz = "0 0 0" />
      <origin xyz="0 0 0" rpy="-1.5708 0 -1.5708"/>
      <parent link="camera_visor"/>
      <child link="optical_link"/>
  </joint>
  

  <gazebo reference="camera_base_link">
    <sensor name="rgbd_camera" type="depth">
      <update_rate>30</update_rate>
      <camera>
        <horizontal_fov>1.11697778</horizontal_fov>
        <vertical_fov>0.6283</vertical_fov>
        <image>
          <width>1280</width>
          <height>720</height>
          <format>B8G8R8</format>
        </image>
        <depth_camera>
          <output>depths</output>
        </depth_camera>
        <clip>
          <near>0.1</near>
          <far>1000.0</far>
        </clip>
      </camera>
      <plugin name="rgbd_controller" filename="libgazebo_ros_openni_kinect.so">
        <baseline>0.2</baseline>
        <alwaysOn>true</alwaysOn>
        <updateRate>30.0</updateRate>
        <cameraName>rgbd_ir</cameraName>
        <imageTopicName>/rgbd/color/image_raw</imageTopicName>
        <cameraInfoTopicName>/rgbd/color/camera_info</cameraInfoTopicName>
        <depthImageTopicName>/rgbd/depth/image_raw</depthImageTopicName>
        <depthImageInfoTopicName>/rgbd/depth/camera_info</depthImageInfoTopicName>
        <pointCloudTopicName>/rgbd/depth/points</pointCloudTopicName>
        <frameName>optical_link</frameName>
        <pointCloudCutoff>0.5</pointCloudCutoff>
        <pointCloudCutoffMax>20</pointCloudCutoffMax>
        <distortionK1>0.00000001</distortionK1>
        <distortionK2>0.00000001</distortionK2>
        <distortionK3>0.00000001</distortionK3>
        <distortionT1>0.00000001</distortionT1>
        <distortionT2>0.00000001</distortionT2>
        <CxPrime>0</CxPrime>
        <Cx>0</Cx>
        <Cy>0</Cy>
        <focalLength>0</focalLength>
        <hackBaseline>0</hackBaseline>
      </plugin>
    </sensor>
  </gazebo>

  <gazebo reference="camera_body">
    <material>Gazebo/White </material>
  </gazebo>
  <gazebo reference="camera_base_link">
    <material>Gazebo/Grey</material>
  </gazebo>
  <gazebo reference="camera_visor">
    <material>Gazebo/Black </material>
  </gazebo>

</robot>